Traceback (most recent call last):
  File "./main.cgi", line 23, in <module>
    1/0
ZeroDivisionError: integer division or modulo by zero
Traceback (most recent call last):
  File "/var/www/riskserver/scripts/main.cgi", line 23, in <module>
    1/0
ZeroDivisionError: integer division or modulo by zero
Traceback (most recent call last):
  File "/var/www/riskserver/scripts/main.cgi", line 23, in <module>
    1/0
ZeroDivisionError: integer division or modulo by zero
Traceback (most recent call last):
  File "/var/www/riskserver/scripts/main.cgi", line 23, in <module>
    1/0
ZeroDivisionError: integer division or modulo by zero
Traceback (most recent call last):
  File "/var/www/riskserver/scripts/main.cgi", line 23, in <module>
    1/0
ZeroDivisionError: integer division or modulo by zero
Traceback (most recent call last):
  File "./main.cgi", line 23, in <module>
    1/0
ZeroDivisionError: integer division or modulo by zero
Traceback (most recent call last):
  File "./main.cgi", line 23, in <module>
    1/0
ZeroDivisionError: integer division or modulo by zero
Traceback (most recent call last):
  File "/var/www/riskserver/scripts/main.cgi", line 68, in <module>
    cht.pushm(nmnm,"",mess,"")
  File "/var/www/riskserver/scripts/chat.py", line 30, in pushm
    pickle.dump(self.data, f)
IOError: [Errno 9] Bad file descriptor
Traceback (most recent call last):
  File "/var/www/riskserver/scripts/main.cgi", line 68, in <module>
    cht.pushm(nmnm,"",mess,"")
  File "/var/www/riskserver/scripts/chat.py", line 30, in pushm
    pickle.dump(self.data, f)
IOError: [Errno 9] Bad file descriptor
Traceback (most recent call last):
  File "/var/www/riskserver/scripts/main.cgi", line 68, in <module>
    cht.pushm(nmnm,"",mess,"")
  File "/var/www/riskserver/scripts/chat.py", line 30, in pushm
    pickle.dump(self.data, f)
IOError: [Errno 9] Bad file descriptor
Traceback (most recent call last):
  File "/var/www/riskserver/scripts/main.cgi", line 68, in <module>
    cht.pushm(nmnm,"",mess,"")
  File "/var/www/riskserver/scripts/chat.py", line 28, in pushm
    pickle.dump(self.data, f)
IOError: [Errno 9] Bad file descriptor
Traceback (most recent call last):
  File "/var/www/riskserver/scripts/main.cgi", line 71, in <module>
    f = open('../mainchatinclude.html','w') 
IOError: [Errno 13] Permission denied: '../mainchatinclude.html'
Traceback (most recent call last):
  File "/var/www/riskserver/scripts/main.cgi", line 71, in <module>
    f = open('../mainchatinclude.html','w') 
IOError: [Errno 13] Permission denied: '../mainchatinclude.html'
Traceback (most recent call last):
  File "/var/www/riskserver/scripts/main.cgi", line 71, in <module>
    f = open('../mainchatinclude.html','w') 
IOError: [Errno 13] Permission denied: '../mainchatinclude.html'
Traceback (most recent call last):
  File "/var/www/riskserver/scripts/main.cgi", line 190, in <module>
    </html> '''%(lobbycode,chatcode)
TypeError: not enough arguments for format string
Traceback (most recent call last):
  File "/var/www/riskserver/scripts/main.cgi", line 190, in <module>
    </html> '''%(lobbycode,chatcode)
TypeError: not enough arguments for format string
Traceback (most recent call last):
  File "/var/www/riskserver/scripts/main.cgi", line 106, in <module>
    '''%(identity,identity)
TypeError: not enough arguments for format string
Traceback (most recent call last):
  File "scripts/main.cgi", line 196, in <module>
    </html> '''%(userbar,lobbycode,chatcode)
ValueError: unsupported format character ';' (0x3b) at index 860
Traceback (most recent call last):
  File "/var/www/riskserver/scripts/main.cgi", line 106, in <module>
    '''%(identity,identity)
TypeError: not enough arguments for format string
Traceback (most recent call last):
  File "/var/www/riskserver/scripts/main.cgi", line 74, in <module>
    f.write(cht.getFormat())
  File "/var/www/riskserver/scripts/chat.py", line 49, in getFormat
    if (l[0] == "Guest"):
UnboundLocalError: local variable 'l' referenced before assignment
